Workbook

Sheet OVERALL
A1: Performance till Current Week
A2: OUTCOME | B2: Annual TGT- Original | C2: REVISED-ANNUAL TGT [H2 Plan] | D2: YTD Tgt | E2: YTD ACH | F2: Weekly tgt | G2: Weekly ach. | H2: BALANCE TGT
A3: ENROLMENT
A4: 5 - 6 Years | B4: =RAJASTHAN!B3+'MADHYA PRADESH'!B4+'UTTAR PRADESH'!B4+'UTTAR PRADESH'!B20 -> 220778 | C4: =RAJASTHAN!C3+'MADHYA PRADESH'!C4+'UTTAR PRADESH'!C4+'UTTAR PRADESH'!C20 -> 139359 | F4: 0 | H4: =C4-E4 -> 139359
A5: 7- 14 Years | B5: =RAJASTHAN!B4+'MADHYA PRADESH'!B5+'UTTAR PRADESH'!B5+'UTTAR PRADESH'!B21 -> 211802 | C5: =RAJASTHAN!C4+'MADHYA PRADESH'!C5+'UTTAR PRADESH'!C5+'UTTAR PRADESH'!C21 -> 109631 | H5: =C5-E5 -> 109631
A6: Overall: 5-14 Years | B6: =RAJASTHAN!B5+'MADHYA PRADESH'!B6+'UTTAR PRADESH'!B6+'UTTAR PRADESH'!B22 -> 432580 | C6: =RAJASTHAN!C5+'MADHYA PRADESH'!C6+'UTTAR PRADESH'!C6+'UTTAR PRADESH'!C22 -> 248990 | D6: =RAJASTHAN!D5+'MADHYA PRADESH'!D6+'UTTAR PRADESH'!D6+'UTTAR PRADESH'!D22 -> 179456 | F6: =RAJASTHAN!F5+'MADHYA PRADESH'!F6+'UTTAR PRADESH'!F6+'UTTAR PRADESH'!F22 -> 19064 | H6: =C6-E6 -> 248990
A7: Achvt. %
A8: RETENTION
A9: # Girls Leaders- BS formation | B9: =RAJASTHAN!B9+'MADHYA PRADESH'!B9+'UTTAR PRADESH'!B9+'UTTAR PRADESH'!B25 -> 78930 | C9: =RAJASTHAN!C9+'MADHYA PRADESH'!C9+'UTTAR PRADESH'!C9+'UTTAR PRADESH'!C25 -> 60972 | D9: =RAJASTHAN!D9+'MADHYA PRADESH'!D9+'UTTAR PRADESH'!D9+'UTTAR PRADESH'!D25 -> 47718 | F9: =RAJASTHAN!F9+'MADHYA PRADESH'!F9+'UTTAR PRADESH'!F9+'UTTAR PRADESH'!F25 -> 17451 | H9: =C9-E9 -> 60972
A10: # SMC Members Trained | B10: =RAJASTHAN!B10+'MADHYA PRADESH'!B10+'UTTAR PRADESH'!B10+'UTTAR PRADESH'!B26 -> 64310 | C10: =RAJASTHAN!C10+'MADHYA PRADESH'!C10+'UTTAR PRADESH'!C10+'UTTAR PRADESH'!C26 -> 53941 | D10: =RAJASTHAN!D10+'MADHYA PRADESH'!D10+'UTTAR PRADESH'!D10+'UTTAR PRADESH'!D26 -> 31287 | F10: =RAJASTHAN!F10+'MADHYA PRADESH'!F10+'UTTAR PRADESH'!F10+'UTTAR PRADESH'!F26 -> 4086 | H10: =C10-E10 -> 53941
A11: #Retention Data Verification | B11: =RAJASTHAN!B11+'MADHYA PRADESH'!B11+'UTTAR PRADESH'!B11+'UTTAR PRADESH'!B27 -> 260971 | C11: =RAJASTHAN!C11+'MADHYA PRADESH'!C11+'UTTAR PRADESH'!C11+'UTTAR PRADESH'!C27 -> 260971 | D11: =RAJASTHAN!D11+'MADHYA PRADESH'!D11+'UTTAR PRADESH'!D11+'UTTAR PRADESH'!D27 -> 163505 | F11: =RAJASTHAN!F11+'MADHYA PRADESH'!F11+'UTTAR PRADESH'!F11+'UTTAR PRADESH'!F27 -> 29438 | H11: =C11-E11 -> 260971
A12: Achvt. %
A13: LEARNING
A14: # Learning Beneficiaries-PO | B14: 331875 | C14: 245845 | D14: =RAJASTHAN!D14+'MADHYA PRADESH'!D14+'UTTAR PRADESH'!D14+'UTTAR PRADESH'!D30 -> 111237 | F14: =RAJASTHAN!F14+'MADHYA PRADESH'!F14+'UTTAR PRADESH'!F14+'UTTAR PRADESH'!F30 -> 0 | H14: =C14-E14 -> 245845
A15: Achvt. % | E15: =E14/D14 -> 0
A16: Source | B16: Ops | C16: Ops | D16: Ops | E16: PMS | F16: Ops | G16: PMS

Sheet RAJASTHAN
A1: Performance till Current Week
A2: ENROLMENT | B2: Annual TGT- Original | C2: REVISED-ANNUAL TGT [H2 Plan] | D2: YTD Tgt | E2: YTD ACH | F2: Weekly tgt | G2: Weekly ach. | H2: BALANCE TGT
A3: 5 - 6 Years | B3: 35884 | C3: 30246 | F3: - | H3: =C3-E3 -> 30246
A4: 7- 14 Years | B4: 31012 | C4: 26139 | H4: =C4-E4 -> 26139
A5: RAJ : 5-14 Years | B5: 66896 | C5: 56385 | D5: =29849+4932 -> 34781 | F5: 4933 | H5: =C5-E5 -> 56385
A6: Achvt %
A7: 15-18 Years [RSOS] | B7: 7885 [5000-RSOS; 2885-Mainstream] | C7: 5000 | D7: 7729 | F7: - | H7: =C7-E7 -> 5000
A8: RETENTION
A9: # Girls Leaders | B9: 28457 | C9: 26468 | D9: 22468 | F9: 6219 | H9: =C9-E9 -> 26468
A10: # SMC Members Trained | B10: 21850 | C10: 21850 | D10: =8465+671 -> 9136 | F10: 672 | H10: =C10-E10 -> 21850
A11: #Retention Data Verification | B11: 102728 | C11: 102728 | D11: =40470+8667 -> 49137 | F11: 8667 | H11: =C11-E11 -> 102728
A12: Achvt %
A13: LEARNING
A14: # Learning Beneficiaries-PO | C14: 88892 | D14: 21089 | F14: 0 | H14: =C14-E14 -> 88892
A15: # Learning Beneficiaries-AGP | B15: 19100 | C15: 19100 | D15: 5880 | F15: 1207 | H15: =C15-E15 -> 19100
A16: Achvt % | E16: =(E14+E15)/(D14+D15) -> 0 | G16: =SUM(G14:G15)/SUM(F14:F15) -> 0
B17: PSU | D17: PSU | F17: PSU | H17: PSU | I17: PSU
A18: District | B18: Enrolment (YTD) | F18: Retention | H18: Learning | J18: Overall
B19: Ach vs Tgt | C19: High Risk Errors | D19: D2D Enrolments per Cluster | E19: %D2D | F19: Ach vs Tgt (YTD) (Data collection+SMC+BSF+GLT) | G19: Quality Assessment | H19: Ach vs Tgt (YTD) | I19: Quality Assessment | J19: District RAG Status
B20: source from PMS & targets provided by Ops | C20: Source from CV data | D20: Average D2D enrolments per FC/cluster | E20: % of D2D enrolments (with SR number And CIOOSG) | F20: source from PMS & targets provided by Ops | G20: Spot check assessment | H20: source from PMS & targets provided by Ops | I20: source from CRO data | J20: Derive from performance
A21: AJMER | C21: 0.05 | D21: 49 | E21: 0.96 | F21: 0.99 | G21: Green | H21: 0.97 | I21: Amber | J21: Amber
A22: BANSWARA | C22: 0.08 | D22: 79 | E22: 0.99 | F22: 1.65 | G22: Green | H22: 1.1 | I22: Amber | J22: Green
A23: BHILWARA | C23: 0.01 | D23: 50 | E23: 1 | F23: 1.2 | G23: Green | H23: NA | I23: NA | J23: Green
A24: BUNDI | C24: 0.13 | D24: 74 | E24: 1 | F24: 0.74 | G24: Green | H24: 0.96 | I24: Amber | J24: Amber
A25: JALORE | C25: 0.05 | D25: 100 | E25: 1 | F25: 0.59 | G25: Green | H25: 0.91 | I25: Red | J25: Red
A26: JHALAWAR | C26: 0.08 | D26: 21 | E26: 1 | F26: 1.19 | G26: Green | H26: 0.94 | I26: Green | J26: Amber
A27: RAJSAMAND | C27: 0.05 | D27: 61 | E27: 0.79 | F27: 0.58 | G27: Green | H27: 1.07 | I27: Green | J27: Amber
A28: SALUMBER | C28: 0.06 | D28: 115 | E28: 1 | F28: 2.06 | G28: Green | H28: 0.84 | I28: Amber | J28: Green
A29: SIROHI | C29: 0.08 | D29: 59 | E29: 0.94 | F29: 0.69 | G29: Green | H29: 0.87 | I29: Green | J29: Green
A30: UDAIPUR | C30: 0.08 | D30: 96 | E30: 1 | F30: 0.79 | G30: Green | H30: 0.86 | I30: Amber | J30: Green
A31: Total | C31: 0.07 | D31: 73 | E31: 0.97 | F31: 1.08 | G31: Green | H31: 0.96 | I31: Amber | J31: Green
B32: Ach vs Tgt (YTD) | C32: High-risk errors | D32: D2D Enrolments per Cluster | E32: D2D/ CIOOSG enrolments | F32: Ach vs Tgt (YTD) | G32: Quality Assessment | H32: Ach vs Tgt (YTD) | I32: Quality Assessment | J32: District RAG Status
A33: Red | B33: Less than 60% | C33: 10%+ | D33: less than 50 | E33: less than 60% | F33: Less than 60% | G33: Significant improvement required | H33: Less than 60% | I33: Overall star rating 1 or 2 | J33: Reds in 2 out of 3 outcomes (E,R,L)
A34: Amber | B34: 60-80% | C34: 8-10% | D34: 50 to 80 | E34: 60-90% | F34: 60-80% | G34: Some improvement required | H34: 60-80% | I34: Overall star rating 3 | J34: Reds in 1 out of 3 outcomes
A35: Green | B35: 80%+ | C35: less than 8% | D35: greater than 80 | E35: >90% | F35: 80%+ | G35: Mostly high quality | H35: 80%+ | I35: Overall star rating 4 or 5 | J35: No reds

Sheet MADHYA PRADESH
A1: Performance till Current Week
A2: OUTCOME | B2: Annual TGT- Original | C2: REVISED-ANNUAL TGT [H2 Plan] | D2: YTD target | E2: YTD ACH | F2: Weekly tgt | G2: Weekly ach. | H2: BALANCE TGT
A3: ENROLMENT
A4: 5 - 6 Years | B4: 99299 | C4: 52662 | F4: - | G4: 393 | H4: =C4-E4 -> 52662
A5: 7- 14 Years | B5: 109114 | C5: 36183 | F5: - | G5: 610 | H5: =C5-E5 -> 36183
A6: MP: 5-14 Years | B6: 208413 | C6: 88845 | D6: 68620 | F6: 8929 | G6: 1003 | H6: =C6-E6 -> 88845
A7: Achvt % | G7: =G6/F6 -> 0.11233061
A8: RETENTION | G8: =G6/F6 -> 0.11233061
A9: # Girls Leaders | B9: 21067 | C9: 17342 | D9: 10262 | F9: 7212 | G9: 13 | H9: =C9-E9 -> 17342
A10: # SMC Members Trained | B10: 18520 | C10: 16131 | D10: 12039 | F10: 1170 | G10: 7 | H10: =C10-E10 -> 16131
A11: #Retention Data Verification | B11: 87448 | C11: 87448 | D11: 70355 | F11: 12318 | G11: 6276 | H11: =C11-E11 -> 87448
A12: Achvt % | G12: =SUM(G9:G11)/SUM(F9:F11) -> 0.30415459
A13: LEARNING
A14: # Learning Beneficiaries-PO | B14: 96575 | C14: 49736 | D14: 38519 | F14: 0 | G14: 205 | H14: =C14-E14 -> 49736
A15: # Learning Beneficiaries-AGP | B15: 3345 | C15: 3345 | D15: 935 | F15: 935 | G15: 0
A16: Achvt % | E16: =E14/D14 -> 0 | G16: NA
A19: District | B19: Enrolment (YTD) | F19: Retention | H19: Learning | J19: Overall
B20: Ach vs Tgt | C20: High Risk Errors | D20: D2D Enrolments per Cluster | E20: %D2D | F20: Ach vs Tgt (YTD) (Data collection+SMC+BSF+GLT) | G20: Quality Assessment | H20: Ach vs Tgt (YTD) | I20: Quality Assessment | J20: District RAG Status
B21: source from PMS & targets provided by Ops | C21: source from CV data | D21: Average D2D enrolments per FC/cluster | E21: % of D2D enrolments (with SR number And CIOOSG) | F21: source from PMS & targets provided by Ops | G21: Spot check assessment | H21: source from PMS & targets provided by Ops | I21: source from CRO data | J21: Derive from performance
A22: ALIRAJPUR | C22: 0.08 | D22: 107 | E22: 0.82 | F22: 0.76 | G22: Green | H22: 0.77 | I22: Amber | J22: Green
A23: BARWANI | C23: 0.05 | D23: 149 | E23: 0.76 | F23: 1.05 | G23: Green | H23: 1.2 | I23: Amber | J23: Green
A24: DHAR | C24: 0.03 | D24: 92 | E24: 0.83 | F24: 1.15 | G24: Green | H24: 0.99 | I24: Amber | J24: Green
A25: JHABUA | C25: 0.05 | D25: 83 | E25: 0.85 | F25: 0.91 | G25: Green | H25: 1.05 | I25: Amber | J25: Green
A26: KHALWA | C26: 0.06 | D26: 192 | E26: 1 | F26: 1.12 | G26: Green | H26: 1.27 | I26: Amber | J26: Green
A27: KHANDWA | C27: 0.04 | D27: 103 | E27: 1 | F27: 1.15 | G27: Amber | H27: 0.62 | I27: Amber | J27: Green
A28: Total | C28: 0.05 | D28: 110 | E28: 0.84 | F28: 1 | G28: Green | H28: 0.92 | I28: Amber | J28: Green
B29: Ach vs Tgt | C29: High Risk Errors | D29: D2D Enrolments per Cluster | E29: D2D/ CIOOSG enrolments | F29: Ach vs Tgt (YTD) | G29: Quality Assessment | H29: Ach vs Tgt (YTD) | I29: Quality Assessment | J29: District RAG Status
A30: Red | B30: Less than 60% | C30: 10%+ | D30: less than 50 | E30: less than 60% | F30: Less than 60% | G30: Significant improvement required | H30: Less than 60% | I30: Overall star rating 1 or 2 | J30: Reds in 2 out of 3 outcomes (E,R,L)
A31: Amber | B31: 60-80% | C31: 8-10% | D31: 50 to 80 | E31: 60-90% | F31: 60-80% | G31: Some improvement required | H31: 60-80% | I31: Overall star rating 3 | J31: Reds in 1 out of 3 outcomes
A32: Green | B32: 80%+ | C32: less than 8% | D32: greater than 80 | E32: >90% | F32: 80%+ | G32: Mostly high quality | H32: 80%+ | I32: Overall star rating 4 or 5 | J32: No reds

Sheet UTTAR PRADESH
A1: Performance till current week
A2: OUTCOME | B2: Annual TGT- Original | C2: REVISED-ANNUAL TGT [H2 Plan] | D2: YTD Target | E2: YTD ACH | F2: Weekly tgt | G2: Weekly ach. | H2: BALANCE TGT
A3: ENROLMENT
A4: 5 - 6 Years | B4: 67184 | C4: 45433 | F4: 0 | H4: =C4-E4 -> 45433
A5: 7- 14 Years | B5: 59401 | C5: 36847 | F5: 0 | H5: =C5-E5 -> 36847
A6: UP : 5-14 Years | B6: =SUM(B4:B5) -> 126585 | C6: 82280 | D6: 59141 | F6: 4226 | H6: =C6-E6 -> 82280
A7: Achvt %
A8: RETENTION
A9: # Girls Leaders | B9: 25974 | C9: 13730 | D9: 11556 | F9: 2174 | H9: =C9-E9 -> 13730
A10: # SMC Members Trained | B10: 19980 | C10: 13320 | D10: 7572 | F10: 1634 | H10: =C10-E10 -> 13320
A11: #Retention Data Verification | B11: 50631 | C11: 50631 | D11: 35000 | F11: 7000 | H11: =C11-E11 -> 50631
A12: Achvt %
A13: LEARNING
A14: # Learning Beneficiaries-PO | B14: 1,12,980 | C14: 86248 | D14: 41069 | F14: 0 | H14: =C14-E14 -> 86248
A15: Achvt % | E15: =E14/D14 -> 0 | G15: NA
A17: Performance till current week (Sidhi)
A18: OUTCOME | B18: Annual TGT- Original | C18: REVISED-ANNUAL TGT [H2 Plan] | D18: YTD Target | E18: YTD ACH | F18: Weekly tgt | G18: Weekly ach. | H18: BALANCE TGT
A19: ENROLMENT
A20: 5 - 6 Years | B20: 18411 | C20: 11018 | F20: 0 | H20: =C20-E20 -> 11018
A21: 7- 14 Years | B21: 12275 | C21: 10462 | F21: 0 | H21: =C21-E21 -> 10462
A22: UP : 5-14 Years | B22: 30686 | C22: 21480 | D22: 16914 | F22: 976 | H22: =C22-E22 -> 21480
A23: Achvt %
A24: RETENTION
A25: # Girls Leaders | B25: 3432 | C25: 3432 | D25: 3432 | F25: 1846 | H25: =C25-E25 -> 3432
A26: # SMC Members Trained | B26: 3960 | C26: 2640 | D26: 2540 | F26: 610 | H26: =C26-E26 -> 2640
A27: #Retention Data Verification | B27: 20164 | C27: 20164 | D27: 9013 | F27: 1453 | H27: =C27-E27 -> 20164
A28: Achvt %
A29: LEARNING
A30: # Learning Beneficiaries-PO | B30: 28935 | C30: 974 | D30: 10560 | F30: 0 | G30: 9 | H30: =C30-E30 -> 974
A31: Achvt % | E31: =E30/D30 -> 0 | G31: NA
A33: District | B33: Enrolment (YTD) | F33: Retention | H33: Learning | J33: Overall
B34: Ach vs Tgt | C34: High Risk Errors | D34: D2D Enrolments per Cluster | E34: %D2D | F34: Ach vs Tgt (YTD) (Data collection+SMC+BSF+GLT) | G34: Quality Assessment | H34: Ach vs Tgt (YTD) | I34: Quality Assessment | J34: District RAG Status
B35: source from PMS & targets provided by Ops | C35: source from CV data | D35: Average D2D enrolments per FC/cluster | E35: % of D2D enrolments (with SR number And CIOOSG) | F35: source from PMS & targets provided by Ops | G35: Spot check assessment | H35: source from PMS & targets provided by Ops | I35: source from CRO data | J35: Derive from performance
A36: CHITRAKOOT | C36: 0.04 | D36: 107 | E36: 0.99 | F36: 0.96 | G36: Green | H36: 1 | I36: Green | J36: Green
A37: FATEHPUR | C37: 0.07 | D37: 63 | E37: 1 | F37: 0.25 | G37: Amber | H37: 1.18 | I37: Amber | J37: Amber
A38: PRAYAGRAJ | C38: 0.09 | D38: 21 | E38: 1 | F38: 0.04 | G38: NA | H38: 1.04 | I38: Amber | J38: Red
A39: ROBERTSGANJ | C39: 0.1 | D39: 70 | E39: 1 | F39: 0.18 | G39: Amber | H39: 1.09 | I39: Green | J39: Amber
A40: SIDHI | C40: 0.07 | D40: 90 | E40: 1 | F40: 1.25 | G40: Red | H40: =11122/10560 -> 1.0532197 | I40: Amber | J40: Amber
A41: Total | C41: 0.07 | D41: 74 | E41: 1 | F41: 0.87 | G41: Red | H41: 1.07 | I41: Amber | J41: Amber
B42: Ach vs Tgt | C42: High-risk errors | D42: D2D Enrolments per Cluster | E42: D2D/ CIOOSG enrolments | F42: Ach vs Tgt (YTD) | G42: Quality Assessment | H42: Ach vs Tgt (YTD) | I42: Quality Assessment | J42: District RAG Status
...

Sheet  WEEK - Backup
E1: 44531 | M1: 44562 | U1: 44593 | AC1: 44621
E2: Week-1 Target | F2: Week-1 Ach. | G2: Week-2 Target | H2: Week-2 Ach. | I2: Week-3 Target | J2: Week-3 Ach. | K2: Week-4 Target | L2: Week-4 Ach. | M2: Week-1 Target | N2: Week-1 Ach. | O2: Week-2 Target | P2: Week-2 Ach. | Q2: Week-3 Target | R2: Week-3 Ach. | S2: Week-4 Target | T2: Week-4 Ach. | U2: Week-1 Target | V2: Week-1 Ach. | W2: Week-2 Target | X2: Week-2 Ach. | Y2: Week-3 Target | Z2: Week-3 Ach. | AA2: Week-4 Target | AB2: Week-4 Ach. | AC2: Week-1 Target | AD2: Week-1 Ach. | AE2: Week-2 Target | AF2: Week-2 Ach. | AG2: Week-3 Target | AH2: Week-3 Ach. | AI2: Week-4 Target | AJ2: Week-4 Ach.
A3: State | B3: District | C3: Outcome | E3: Manual | F3: PMS | G3: Manual | H3: PMS | I3: Manual | J3: PMS | K3: Manual | L3: PMS | M3: Manual | N3: PMS | O3: Manual | P3: PMS | Q3: Manual | R3: PMS | S3: Manual | T3: PMS | U3: Manual | V3: PMS | W3: Manual | X3: PMS | Y3: Manual | Z3: PMS | AA3: Manual | AB3: PMS | AC3: Manual | AD3: PMS | AE3: Manual | AF3: PMS | AG3: Manual | AH3: PMS | AI3: Manual | AJ3: PMS
A4: Rajasthan | B4: AJMER | C4: Enrolment 5-14 | E4: 0 | F4: 87 | G4: 0 | H4: 36 | I4: 168 | J4: 27 | K4: 142 | L4: 15 | M4: 107 | N4: 3 | O4: 109 | P4: 1 | Q4: 156 | S4: 146 | U4: 146 | W4: 187 | Y4: 185 | AA4: 180 | AC4: 0 | AE4: 0 | AG4: 0 | AI4: 0
A5: Rajasthan | B5: AJMER | C5: # Girls Leaders | E5: 0 | F5: 0 | G5: 0 | H5: 0 | I5: 321 | J5: 0 | K5: 0 | L5: 338 | M5: 803 | N5: 1066 | O5: 803 | P5: 740 | Q5: 803 | S5: 482 | U5: 0 | W5: 0 | Y5: 0 | AA5: 0 | AC5: 0 | AE5: 0 | AG5: 0 | AI5: 0
A6: Rajasthan | B6: AJMER | C6: # SMC Members Trained | E6: 0 | F6: 0 | G6: 0 | H6: 0 | I6: 0 | J6: 0 | K6: 95 | L6: 349 | M6: 0 | N6: 1066 | O6: 0 | P6: 740 | Q6: 64 | S6: 95 | U6: 191 | W6: 238 | Y6: 238 | AA6: 286 | AC6: 191 | AE6: 191 | AG6: 123 | AI6: 0
A7: Rajasthan | B7: AJMER | C7: #Retention Data Verification | E7: 0 | F7: 0 | G7: 0 | H7: 171 | I7: 574 | J7: 1134 | K7: 574 | L7: 0 | M7: 574 | N7: 790 | O7: 527 | P7: 64 | Q7: 0 | S7: 0 | U7: 0 | W7: 0 | Y7: 0 | AA7: 0 | AC7: 0 | AE7: 0 | AG7: 0 | AI7: 0
A8: Rajasthan | B8: AJMER | C8: # Learning Beneficiaries-PO | E8: 0 | F8: Pending | G8: 0 | H8: Pending | I8: 0 | J8: Pending | K8: 0 | L8: Pending | M8: 140 | N8: Pending | O8: 0 | P8: Pending | Q8: 0 | S8: 0 | U8: 0 | W8: 0 | Y8: 0 | AA8: 0 | AC8: 0 | AE8: 0 | AG8: 0 | AI8: 0
A9: Rajasthan | B9: BANSWARA | C9: Enrolment 5-14 | E9: 0 | F9: 423 | G9: 0 | H9: 400 | I9: 402 | J9: 426 | K9: 76 | L9: 326 | M9: 225 | N9: 561 | O9: 1102 | P9: 347 | Q9: 556 | S9: 1011 | U9: 444 | W9: 346 | Y9: 402 | AA9: 928 | AC9: - | AE9: - | AG9: - | AI9: -
A10: Rajasthan | B10: BANSWARA | C10: # Girls Leaders | E10: 0 | F10: 0 | G10: 0 | H10: 0 | I10: 230 | J10: 0 | K10: 0 | L10: 468 | M10: 688 | N10: 675 | O10: 688 | P10: 726 | Q10: 688 | S10: 505 | U10: 789 | W10: 0 | Y10: 0 | AA10: 0 | AC10: 0 | AE10: 0 | AG10: 0 | AI10: 0
A11: Rajasthan | B11: BANSWARA | C11: # SMC Members Trained | E11: 0 | F11: 0 | G11: 0 | H11: 0 | I11: 102 | J11: 0 | K11: 102 | L11: 468 | M11: 0 | N11: 675 | O11: 0 | P11: 726 | Q11: 62 | S11: 102 | U11: 204 | W11: 204 | Y11: 116 | AA11: 0 | AC11: 0 | AE11: 0 | AG11: 0 | AI11: 0
A12: Rajasthan | B12: BANSWARA | C12: #Retention Data Verification | E12: 0 | F12: 12 | G12: 0 | H12: 937 | I12: 1512 | J12: 2981 | K12: 1512 | L12: 0 | M12: 1512 | N12: 3380 | O12: 1512 | P12: 2654 | Q12: 2234 | S12: 4272 | U12: 4272 | W12: 4272 | Y12: 4272 | AA12: 4272 | AC12: 4076 | AE12: 0 | AG12: 0 | AI12: 0
A13: Rajasthan | B13: BANSWARA | C13: # Learning Beneficiaries-PO | E13: 0 | F13: Pending | G13: 0 | H13: Pending | I13: 0 | J13: Pending | K13: 0 | L13: Pending | M13: 0 | N13: Pending | O13: 0 | P13: Pending | Q13: 0 | S13: 0 | U13: 0 | W13: 0 | Y13: 0 | AA13: 0 | AC13: 0 | AE13: 0 | AG13: 0 | AI13: 0
A14: Rajasthan | B14: BHILWARA | C14: Enrolment 5-14 | E14: 0 | F14: 422 | G14: 0 | H14: 63 | I14: 15 | J14: 51 | K14: 45 | L14: 177 | M14: 98 | N14: 57 | O14: 197 | P14: 177 | Q14: 186 | S14: 88 | U14: 0 | W14: 0 | Y14: 0 | AA14: 0 | AC14: - | AE14: - | AG14: - | AI14: -
A15: Rajasthan | B15: BHILWARA | C15: # Girls Leaders | E15: 0 | F15: 0 | G15: 0 | H15: 0 | I15: 292 | J15: 0 | K15: 0 | L15: 663 | M15: 564 | N15: 494 | O15: 600 | P15: 348 | Q15: 0 | S15: 0 | U15: 0 | W15: 0 | Y15: 0 | AA15: 0 | AC15: 0 | AE15: 0 | AG15: 0 | AI15: 0
A16: Rajasthan | B16: BHILWARA | C16: # SMC Members Trained | E16: 0 | F16: 4 | G16: 0 | H16: 0 | I16: 78 | J16: 0 | K16: 78 | L16: 663 | M16: 0 | N16: 511 | O16: 0 | P16: 348 | Q16: 78 | S16: 78 | U16: 154 | W16: 154 | Y16: 154 | AA16: 154 | AC16: 154 | AE16: 154 | AG16: 164 | AI16: 0
A17: Rajasthan | B17: BHILWARA | C17: #Retention Data Verification | E17: 0 | F17: 0 | G17: 0 | H17: 261 | I17: 402 | J17: 125 | K17: 0 | L17: 0 | M17: 0 | N17: 12 | O17: 0 | P17: 4 | Q17: 0 | S17: 0 | U17: 0 | W17: 0 | Y17: 0 | AA17: 0 | AC17: 0 | AE17: 0 | AG17: 0 | AI17: 0
A18: Rajasthan | B18: BHILWARA | C18: # Learning Beneficiaries-PO | E18: 0 | F18: Pending | G18: 0 | H18: Pending | I18: 0 | J18: Pending | K18: 0 | L18: Pending | M18: 0 | N18: Pending | O18: 0 | P18: Pending | Q18: 0 | S18: 0 | U18: 0 | W18: 0 | Y18: 0 | AA18: 0 | AC18: 0 | AE18: 0 | AG18: 0 | AI18: 0
A19: Rajasthan | B19: BUNDI | C19: Enrolment 5-14 | E19: 0 | F19: 100 | G19: 0 | H19: 258 | I19: 195 | J19: 302 | K19: 89 | L19: 329 | M19: 235 | N19: 160 | O19: 745 | P19: 218 | Q19: 402 | S19: 133 | U19: 0 | W19: 0 | Y19: 0 | AA19: 0 | AC19: - | AE19: - | AG19: - | AI19: -
A20: Rajasthan | B20: BUNDI | C20: # Girls Leaders | E20: 0 | F20: 0 | G20: 0 | H20: 0 | I20: 228 | J20: 0 | K20: 0 | L20: 454 | M20: 678 | N20: 52 | O20: 678 | P20: 0 | Q20: 678 | S20: 364 | U20: 0 | W20: 0 | Y20: 0 | AA20: 0 | AC20: 0 | AE20: 0 | AG20: 0 | AI20: 0
A21: Rajasthan | B21: BUNDI | C21: # SMC Members Trained | E21: 0 | F21: 47 | G21: 0 | H21: 10 | I21: 78 | J21: 0 | K21: 78 | L21: 512 | M21: 0 | N21: 68 | O21: 0 | P21: 0 | Q21: 50 | S21: 78 | U21: 156 | W21: 106 | Y21: 106 | AA21: 128 | AC21: 0 | AE21: 0 | AG21: 0 | AI21: 0
A22: Rajasthan | B22: BUNDI | C22: #Retention Data Verification | E22: 0 | F22: 102 | G22: 0 | H22: 628 | I22: 1212 | J22: 404 | K22: 1075 | L22: 0 | M22: 0 | N22: 627 | O22: 0 | P22: 426 | Q22: 0 | S22: 0 | U22: 0 | W22: 0 | Y22: 0 | AA22: 0 | AC22: 0 | AE22: 0 | AG22: 0 | AI22: 0
A23: Rajasthan | B23: BUNDI | C23: # Learning Beneficiaries-PO | E23: 0 | F23: Pending | G23: 0 | H23: Pending | I23: 0 | J23: Pending | K23: 0 | L23: Pending | M23: 121 | N23: Pending | O23: 0 | P23: Pending | Q23: 0 | S23: 0 | U23: 0 | W23: 0 | Y23: 0 | AA23: 0 | AC23: 0 | AE23: 0 | AG23: 0 | AI23: 0
A24: Rajasthan | B24: JALORE | C24: Enrolment 5-14 | E24: 0 | F24: 407 | G24: 0 | H24: 487 | I24: 395 | J24: 438 | K24: 88 | L24: 79 | M24: 195 | N24: 784 | O24: 689 | P24: 87 | Q24: 1290 | S24: 1304 | U24: 1281 | W24: 1051 | Y24: 1174 | AA24: 1279 | AC24: - | AE24: - | AG24: - | AI24: -
A25: Rajasthan | B25: JALORE | C25: # Girls Leaders | E25: 0 | F25: 0 | G25: 0 | H25: 0 | I25: 220 | J25: 0 | K25: 0 | L25: 234 | M25: 698 | N25: 65 | O25: 698 | P25: 0 | Q25: 698 | S25: 590 | U25: 957 | W25: 0 | Y25: 0 | AA25: 0 | AC25: 0 | AE25: 0 | AG25: 0 | AI25: 0
A26: Rajasthan | B26: JALORE | C26: # SMC Members Trained | E26: 0 | F26: 0 | G26: 0 | H26: 0 | I26: 88 | J26: 0 | K26: 88 | L26: 234 | M26: 0 | N26: 65 | O26: 0 | P26: 0 | Q26: 42 | S26: 88 | U26: 176 | W26: 298 | Y26: 298 | AA26: 298 | AC26: 220 | AE26: 94 | AG26: 0 | AI26: 0
A27: Rajasthan | B27: JALORE | C27: #Retention Data Verification | E27: 0 | F27: 213 | G27: 0 | H27: 691 | I27: 989 | J27: 617 | K27: 989 | L27: 13 | M27: 586 | N27: 258 | O27: 0 | P27: 348 | Q27: 0 | S27: 0 | U27: 0 | W27: 0 | Y27: 0 | AA27: 0 | AC27: 0 | AE27: 0 | AG27: 0 | AI27: 0
A28: Rajasthan | B28: JALORE | C28: # Learning Beneficiaries-PO | E28: 0 | F28: Pending | G28: 0 | H28: Pending | I28: 0 | J28: Pending | K28: 0 | L28: Pending | M28: 30 | N28: Pending | O28: 0 | P28: Pending | Q28: 0 | S28: 0 | U28: 0 | W28: 0 | Y28: 0 | AA28: 0 | AC28: 0 | AE28: 0 | AG28: 0 | AI28: 0
A29: Rajasthan | B29: JHALAWAR | C29: Enrolment 5-14 | E29: 0 | F29: 102 | G29: 0 | H29: 74 | I29: 226 | J29: 39 | K29: 93 | L29: 23 | M29: 268 | N29: 191 | O29: 556 | P29: 77 | Q29: 102 | S29: 0 | U29: 0 | W29: 0 | Y29: 0 | AA29: 0 | AC29: - | AE29: - | AG29: - | AI29: -
A30: Rajasthan | B30: JHALAWAR | C30: # Girls Leaders | E30: 0 | F30: 0 | G30: 0 | H30: 0 | I30: 320 | J30: 65 | K30: 0 | L30: 948 | M30: 698 | N30: 360 | O30: 698 | P30: 610 | Q30: 698 | S30: 134 | U30: 0 | W30: 0 | Y30: 0 | AA30: 0 | AC30: 0 | AE30: 0 | AG30: 0 | AI30: 0
A31: Rajasthan | B31: JHALAWAR | C31: # SMC Members Trained | E31: 0 | F31: 0 | G31: 0 | H31: 10 | I31: 98 | J31: 65 | K31: 98 | L31: 948 | M31: 0 | N31: 360 | O31: 0 | P31: 610 | Q31: 72 | S31: 98 | U31: 196 | W31: 368 | Y31: 127 | AA31: 0 | AC31: 0 | AE31: 0 | AG31: 0 | AI31: 0
A32: Rajasthan | B32: JHALAWAR | C32: #Retention Data Verification | E32: 0 | F32: 705 | G32: 0 | H32: 2459 | I32: 1112 | J32: 2876 | K32: 1112 | L32: 34 | M32: 1112 | N32: 1132 | O32: 1112 | P32: 70 | Q32: 1112 | S32: 1112 | U32: 754 | W32: 0 | Y32: 0 | AA32: 0 | AC32: 0 | AE32: 0 | AG32: 0 | AI32: 0
A33: Rajasthan | B33: JHALAWAR | C33: # Learning Beneficiaries-PO | E33: 0 | F33: Pending | G33: 0 | H33: Pending | I33: 0 | J33: Pending | K33: 0 | L33: Pending | M33: 250 | N33: Pending | O33: 0 | P33: Pending | Q33: 0 | S33: 0 | U33: 0 | W33: 0 | Y33: 0 | AA33: 0 | AC33: 0 | AE33: 0 | AG33: 0 | AI33: 0
A34: Rajasthan | B34: RAJSAMAND | C34: Enrolment 5-14 | E34: 0 | F34: 261 | G34: 0 | H34: 189 | I34: 207 | J34: 76 | K34: 86 | L34: 108 | M34: 235 | N34: 61 | O34: 786 | P34: 17 | Q34: 198 | S34: 102 | U34: 0 | W34: 0 | Y34: 0 | AA34: 0 | AC34: - | AE34: - | AG34: - | AI34: -
A35: Rajasthan | B35: RAJSAMAND | C35: # Girls Leaders | E35: 0 | F35: 0 | G35: 0 | H35: 0 | I35: 230 | J35: 0 | K35: 0 | L35: 0 | M35: 698 | N35: 607 | O35: 698 | P35: 464 | Q35: 698 | S35: 527 | U35: 230 | W35: 0 | Y35: 0 | AA35: 0 | AC35: 0 | AE35: 0 | AG35: 0 | AI35: 0
A36: Rajasthan | B36: RAJSAMAND | C36: # SMC Members Trained | E36: 0 | F36: 0 | G36: 0 | H36: 0 | I36: 96 | J36: 0 | K36: 96 | L36: 0 | M36: 0 | N36: 607 | O36: 0 | P36: 464 | Q36: 58 | S36: 96 | U36: 192 | W36: 266 | Y36: 266 | AA36: 266 | AC36: 184 | AE36: 0 | AG36: 0 | AI36: 0
A37: Rajasthan | B37: RAJSAMAND | C37: #Retention Data Verification | E37: 0 | F37: 0 | G37: 0 | H37: 403 | I37: 1010 | J37: 692 | K37: 1010 | L37: 0 | M37: 1010 | N37: 543 | O37: 1010 | P37: 744 | Q37: 994 | S37: 0 | U37: 0 | W37: 0 | Y37: 0 | AA37: 0 | AC37: 0 | AE37: 0 | AG37: 0 | AI37: 0
A38: Rajasthan | B38: RAJSAMAND | C38: # Learning Beneficiaries-PO | E38: 0 | F38: Pending | G38: 0 | H38: Pending | I38: 0 | J38: Pending | K38: 0 | L38: Pending | M38: 96 | N38: Pending | O38: 0 | P38: Pending | Q38: 0 | S38: 0 | U38: 0 | W38: 0 | Y38: 0 | AA38: 0 | AC38: 0 | AE38: 0 | AG38: 0 | AI38: 0
A39: Rajasthan | B39: SALUMBER | C39: Enrolment 5-14 | E39: 0 | F39: 251 | G39: 0 | H39: 543 | I39: 395 | J39: 536 | K39: 132 | L39: 358 | M39: 341 | N39: 162 | O39: 949 | P39: 106 | Q39: 686 | S39: 819 | U39: 435 | W39: 514 | Y39: 395 | AA39: 348 | AC39: 0 | AE39: - | AG39: - | AI39: -
A40: Rajasthan | B40: SALUMBER | C40: # Girls Leaders | E40: 0 | F40: 0 | G40: 0 | H40: 0 | I40: 191 | J40: 0 | K40: 0 | L40: 298 | M40: 478 | N40: 780 | O40: 478 | P40: 403 | Q40: 478 | S40: 287 | U40: 0 | W40: 0 | Y40: 0 | AA40: 0 | AC40: 0 | AE40: 0 | AG40: 0 | AI40: 0
...

Sheet WEEKLY
I1: 44916 | Q1: 44583 | Y1: 44614 | AG1: 44642
I2: Week-1 Target | J2: Week-1 Ach. | K2: Week-2 Target | L2: Week-2 Ach. | M2: Week-3 Target | N2: Week-3 Ach. | O2: Week-4 Target | P2: Week-4 Ach. | Q2: Week-1 Target | R2: Week-1 Ach. | S2: Week-2 Target | T2: Week-2 Ach. | U2: Week-3 Target | V2: Week-3 Ach. | W2: Week-4 Target | X2: Week-4 Ach. | Y2: Week-1 Target | Z2: Week-1 Ach. | AA2: Week-2 Target | AB2: Week-2 Ach. | AC2: Week-3 Target | AD2: Week-3 Ach. | AE2: Week-4 Target | AF2: Week-4 Ach. | AG2: Week-1 Target | AH2: Week-1 Ach. | AI2: Week-2 Target | AJ2: Week-2 Ach. | AK2: Week-3 Target | AL2: Week-3 Ach. | AM2: Week-4 Target | AN2: Week-4 Ach.
A3: State | B3: District | C3: Outcome | D3: YTD achv. Till Nov | E3: Remaining KMI | F3: YTD Target | G3: Total Target | H3: Total Ach | I3: Manual | J3: PMS | K3: Manual | L3: PMS | M3: Manual | N3: PMS | O3: Manual | P3: PMS | Q3: Manual | R3: PMS | S3: Manual | T3: PMS | U3: Manual | V3: PMS | W3: Manual | X3: PMS | Y3: Manual | Z3: PMS | AA3: Manual | AB3: PMS | AC3: Manual | AD3: PMS | AE3: Manual | AF3: PMS | AG3: Manual | AH3: PMS | AI3: Manual | AJ3: PMS | AK3: Manual | AL3: PMS | AM3: Manual | AN3: PMS

Sheet YTD - Target
A1: State | B1: District | C1: Outcome | D1: Weekly Target | E1: YTD Target | L1: Outcome
A2: Rajasthan | B2: AJMER | C2: Enrolment 5-14 | D2: 156 | E2: 2173 | L2: # Girls Leaders | N2: # Learning Beneficiaries-AGP | P2: # Learning Beneficiaries-PO | R2: # SMC Members Trained | T2: #Retention Data Verification | V2: Enrolment 5-14 | X2: Total SUM of Weekly Target | Y2: Total Sum of YTD Target
A3: Rajasthan | B3: AJMER | C3: # Girls Leaders | D3: 803 | E3: 2730 | K3: State | L3: SUM of Weekly Target | M3: Sum of YTD Target | N3: SUM of Weekly Target | O3: Sum of YTD Target | P3: SUM of Weekly Target | Q3: Sum of YTD Target | R3: SUM of Weekly Target | S3: Sum of YTD Target | T3: SUM of Weekly Target | U3: Sum of YTD Target | V3: SUM of Weekly Target | W3: Sum of YTD Target
A4: Rajasthan | B4: AJMER | C4: # SMC Members Trained | D4: 64 | E4: 346 | K4: MP | L4: 7212 | M4: 10262 | P4: 0 | Q4: 38519 | R4: 1170 | S4: 12039 | T4: 12318 | U4: 70355 | V4: 8929 | W4: 68620 | X4: 29629 | Y4: 199795
A5: Rajasthan | B5: AJMER | C5: #Retention Data Verification | D5: 0 | E5: 2249 | K5: Rajasthan | L5: 6219 | M5: 22468 | N5: 1207 | O5: 5880 | P5: 0 | Q5: 21089 | R5: 672 | S5: 9137 | T5: 8667 | U5: 49137 | V5: 4933 | W5: 34781 | X5: 21698 | Y5: 142492
A6: Rajasthan | B6: AJMER | C6: # Learning Beneficiaries-PO | D6: 0 | E6: 2280 | K6: Sidhi | L6: 1846 | M6: 3432 | P6: 0 | Q6: 10560 | R6: 610 | S6: 2540 | T6: 1453 | U6: 9013 | V6: 976 | W6: 16914 | X6: 4885 | Y6: 42459
A7: Rajasthan | B7: AJMER | C7: # Learning Beneficiaries-AGP | D7: 100 | E7: 400 | K7: UP | L7: 2174 | M7: 11556 | P7: 0 | Q7: 41069 | R7: 1634 | S7: 7572 | T7: 7000 | U7: 35000 | V7: 4226 | W7: 59141 | X7: 15034 | Y7: 154338
A8: Rajasthan | B8: BANSWARA | C8: Enrolment 5-14 | D8: 556 | E8: 5094 | K8: Grand Total | L8: 17451 | M8: 47718 | N8: 1207 | O8: 5880 | P8: 0 | Q8: 111237 | R8: 4086 | S8: 31288 | T8: 29438 | U8: 163505 | V8: 19064 | W8: 179456 | X8: 71246 | Y8: 539084
A9: Rajasthan | B9: BANSWARA | C9: # Girls Leaders | D9: 688 | E9: 2294
A10: Rajasthan | B10: BANSWARA | C10: # SMC Members Trained | D10: 62 | E10: 2824
A11: Rajasthan | B11: BANSWARA | C11: #Retention Data Verification | D11: 2234 | E11: 8282
A12: Rajasthan | B12: BANSWARA | C12: # Learning Beneficiaries-PO | D12: 0 | E12: 4969
A13: Rajasthan | B13: BANSWARA | C13: # Learning Beneficiaries-AGP | E13: 60
A14: Rajasthan | B14: BHILWARA | C14: Enrolment 5-14 | D14: 186 | E14: 921
A15: Rajasthan | B15: BHILWARA | C15: # Girls Leaders | D15: 0 | E15: 1456
A16: Rajasthan | B16: BHILWARA | C16: # SMC Members Trained | D16: 78 | E16: 234
A17: Rajasthan | B17: BHILWARA | C17: #Retention Data Verification | D17: 0 | E17: 402
A18: Rajasthan | B18: BHILWARA | C18: # Learning Beneficiaries-PO | D18: 0 | E18: 0
A19: Rajasthan | B19: BHILWARA | C19: # Learning Beneficiaries-AGP | E19: 0
A20: Rajasthan | B20: BUNDI | C20: Enrolment 5-14 | D20: 402 | E20: 1851
A21: Rajasthan | B21: BUNDI | C21: # Girls Leaders | D21: 678 | E21: 2262
A22: Rajasthan | B22: BUNDI | C22: # SMC Members Trained | D22: 50 | E22: 576
A23: Rajasthan | B23: BUNDI | C23: #Retention Data Verification | D23: 0 | E23: 2287
A24: Rajasthan | B24: BUNDI | C24: # Learning Beneficiaries-PO | D24: 0 | E24: 920
A25: Rajasthan | B25: BUNDI | C25: # Learning Beneficiaries-AGP | E25: 240
A26: Rajasthan | B26: JALORE | C26: Enrolment 5-14 | D26: 1290 | E26: 3751
A27: Rajasthan | B27: JALORE | C27: # Girls Leaders | D27: 698 | E27: 2314
A28: Rajasthan | B28: JALORE | C28: # SMC Members Trained | D28: 42 | E28: 428
A29: Rajasthan | B29: JALORE | C29: #Retention Data Verification | D29: 0 | E29: 2564
A30: Rajasthan | B30: JALORE | C30: # Learning Beneficiaries-PO | D30: 0 | E30: 2280
A31: Rajasthan | B31: JALORE | C31: # Learning Beneficiaries-AGP | D31: 320 | E31: 1620
A32: Rajasthan | B32: JHALAWAR | C32: Enrolment 5-14 | D32: 102 | E32: 1537
A33: Rajasthan | B33: JHALAWAR | C33: # Girls Leaders | D33: 698 | E33: 2414
A34: Rajasthan | B34: JHALAWAR | C34: # SMC Members Trained | D34: 72 | E34: 1661
A35: Rajasthan | B35: JHALAWAR | C35: #Retention Data Verification | D35: 1112 | E35: 5560
A36: Rajasthan | B36: JHALAWAR | C36: # Learning Beneficiaries-PO | D36: 0 | E36: 980
A37: Rajasthan | B37: JHALAWAR | C37: # Learning Beneficiaries-AGP | E37: 80
A38: Rajasthan | B38: RAJSAMAND | C38: Enrolment 5-14 | D38: 198 | E38: 2664
A39: Rajasthan | B39: RAJSAMAND | C39: # Girls Leaders | D39: 698 | E39: 2324
A40: Rajasthan | B40: RAJSAMAND | C40: # SMC Members Trained | D40: 58 | E40: 380
...

Sheet TRENDS
A2: Outcome | B2: Enrolment
C3: Weekly Achievment against target
A4: State | B4: District | C4: Week 1 | D4: Week 2 | E4: Week 3 | F4: Week 4 | G4: Week 5 | H4: Week 6 | I4: Insight
A5: MP | B5: D1 | C5: -0.1 | D5: -0.2 | E5: -0.1 | F5: -0.05 | G5: -0.15 | H5: -0.1 | I5: D1 is consistently underperforming. Estimates may be unrealistic or support may be required.
B6: D2 | C6: 0.1 | D6: 0.15 | E6: -0.1 | F6: 0.1 | G6: -0.05 | H6: 0.05 | I6: D2 performance is erratic and no pattern visible.
C13: Quality - Trends in Quality Assessment (High-risk errors)
A14: State | B14: District | C14: Week 1 | D14: Week 2 | E14: Week 3 | F14: Week 4 | G14: Week 5 | H14: Week 6 | I14: Insight | J14: Action Recommended
C15: YTD | D15: YTD | E15: YTD | F15: YTD | G15: YTD | H15: YTD
A16: MP | B16: D1 | C16: Green | D16: Green | E16: Amber | F16: Amber | G16: Red | H16: Red | I16: D1 quality assessment steadily getting worse | J16: #of matching errors is of concern. Analyse by FC and provide support to improve
B17: D2 | C17: Amber | D17: Red | E17: Red | F17: Red | G17: Amber | H17: Amber | I17: D2 quality assessment steadily getting better
B18: D3 | C18: Green | D18: Amber | E18: Amber | F18: Amber | G18: Amber | H18: Amber | I18: D3 quality is within acceptable thresholds but could be improved

Sheet DEFINITIONS
B2: Cut off date | C2: YTD-Till 23th Jan 2021, Weekly- 17 Jan 2022 to 23rd Jan 2022
B3: Enrollment | C3: # OOSG 5-14, class 1-8, current program year, complete SR but only D2D,GSA and CIOOSG.
B4: # Girl Leaders | C4: # All registered girls where Bal Sabha Formation status is Bal Sabha Formed
B5: # SMC Members Trained | C5: # Members trained and activity approved by IO + Community Level SMC Meeting's Member
B6: Retention Data Collection | C6: # Verified OOSC
B7: Retention% | C7: # Verified OOSC/Targeted OOSC
B8: Learning Beneficiaries | C8: # Beneficiaries ( both girls and boys) who attended at least one CBL session in either Camp 1 or 2 or both. Weekly from Session 1 Attendance(last 7 Days)
B9: CBL Conversion% | C9: # Learning beneficiaries who got enrolled this program year against D2D/CIOOSG # Learning beneficiaries
B10: % D2D Enrolments | C10: # (D2D + CIOOSG + GSA) against # OOSG whose matching is not pending- Quality Enrolment Girls
C11: Where age: 5-14, class: 1-8, SR: Complete, Enrolment Year: Current program year
B12: D2D Enrolments per FC | C12: Average # (D2D + CIOOSG + GSA) Girls enrolments per FC

Sheet Trend2
A1: State | B1: District | C1: Week 1 | D1: Week 2 | E1: Week 3 | F1: Week 4 | G1: Week 5 | H1: Week 6
A2: Rajasthan | B2: AJMER
A3: Rajasthan | B3: BANSWARA
A4: Rajasthan | B4: BHILWARA
A5: Rajasthan | B5: BUNDI
A6: Rajasthan | B6: JALORE
A7: Rajasthan | B7: JHALAWAR
A8: Rajasthan | B8: RAJSAMAND
A9: Rajasthan | B9: SALUMBER
A10: Rajasthan | B10: SIROHI
A11: Rajasthan | B11: UDAIPUR
A12: MADHYA PRADESH | B12: ALIRAJPUR
A13: MADHYA PRADESH | B13: BARWANI
... A22: UTTAR PRADESH | B22: ROBERTSGANJ
